Workbook

Sheet README
A1: ARWC case inventory (draft v0.1, 14 October 2026)
A2: Purpose: one list of every case already in the registry and every publicly documented case that could be screened for inclusion. Candidate rows are leads, not coded records.
A4: Status values
A5: Verified record: published and confirmed by a co-developer.
A6: Provisional record: coded to Codebook v1.0 and source-checked; awaiting co-developer confirmation.
A7: Pending: meets the criteria on the sources found, but the official act cannot yet be cited.
A8: Excluded (worked example): screened and excluded; kept as a worked example.
A9: Set aside in pilot: considered in the second coded set and not used (never final, or scope undecided).
A10: Candidate - not screened: listed from an existing archive, database or public reporting; not yet screened against the ARWC criteria.
A12: Reading the candidate rows
A13: Years, places and outcomes are as reported by the lead source and have not been checked against judgments. Rows marked 'as recalled; to confirm' were added from general knowledge of well-known cases and need a source before use.
A14: Finality check is a first guess: Likely = the conviction appears to have been final before correction; Doubtful = correction may have come on ordinary appeal or remand (ARWC excludes these); To check = not enough information.
... A20: To refresh the web page, run: python3 tools/build_inventory_html.py data/ARWC_Case_Inventory.xlsx inventory.html

Sheet Cases
A1: Inventory ID | B1: ARWC ID | C1: Status | D1: Person(s) | E1: Local name | F1: Jurisdiction | G1: Place | H1: Offense (as reported) | I1: Final conviction (year) | J1: Correction (year) | K1: Correction (as reported) | L1: Preliminary category | M1: Finality check | N1: Lead source | O1: Source URL | P1: Notes / to check
A2: INV-001 | B2: ARWC-CHN-0001 | C2: Verified record | D2: Nie Shubin | E2: 聂树斌 | F2: China | G2: Hebei | H2: Murder and rape | I2: 1995 | J2: 2016 | K2: Retrial acquittal (SPC); state compensation 2017 | L2: A, B | M2: Pass | N2: ARWC record; also USALI archive | O2: https://usali.org/wc-case-archive/nie-shubin-case
A3: INV-002 | B3: ARWC-JPN-001 | C3: Provisional record | D3: Hakamada Iwao | E3: 袴田巌 | F3: Japan | G3: Shizuoka | H3: Robbery-homicide, arson | I3: 1980 | J3: 2024 | K3: Retrial acquittal | L3: A | M3: Pass | N3: ARWC first set | O3: https://www.courts.go.jp/hanrei/93622/detail4/index.html | P3: Awaiting co-developer confirmation
A4: INV-003 | B4: ARWC-JPN-002 | C4: Provisional record | D4: Sugaya Toshikazu | E4: 菅家利和 | F4: Japan | G4: Tochigi | H4: Kidnapping, murder | I4: 2000 | J4: 2010 | K4: Retrial acquittal; police review | L4: A, B | M4: Pass | N4: ARWC first set | O4: https://www.courts.go.jp/hanrei/80213/detail4/index.html | P4: Ashikaga case
A5: INV-004 | B5: ARWC-TWN-001 | C5: Provisional record | D5: Chiang Kuo-ching | E5: 江國慶 | F5: Taiwan | G5: Taipei | H5: Rape (child killed) | I5: 1997 | J5: 2010 | K5: Control Yuan correction 2010; military retrial acquittal 2011 | L5: A, B | M5: Pass | N5: ARWC first set | O5: https://cybsbox.cy.gov.tw/CYBSBoxSSL/edoc/download/50046 | P5: Executed 1997; posthumous
A6: INV-005 | B6: ARWC-CHN-002 | C6: Provisional record | D6: Zhang Yuhuan | E6: 张玉环 | F6: China | G6: Jiangxi | H6: Intentional homicide | I6: 2001 | J6: 2020 | K6: Retrial acquittal; state compensation | L6: A, B | M6: Pass | N6: ARWC first set; also USALI archive | O6: https://usali.org/wc-case-archive/zhang-yuhuan-murder-case
A7: INV-006 | B7: ARWC-KOR-001 | C7: Provisional record | D7: Yoon Sung-yeo | E7: 윤성여 | F7: Korea | G7: Gyeonggi | H7: Murder, rape resulting in death | I7: 1989 | J7: 2020 | K7: Retrial acquittal; state-damages judgment 2022 | L7: A, B | M7: Pass (date to confirm) | N7: ARWC first set | O7: https://www.lawtimes.co.kr/news/articleView.html?idxno=166641 | P7: Eighth Hwaseong case
A8: INV-007 | B8: ARWC-IND-001 | C8: Provisional record | D8: Ankush Maruti Shinde and five others | F8: India | G8: Maharashtra | H8: Murder, gang rape, dacoity | I8: 2009 | J8: 2019 | K8: Supreme Court acquittal after recall on review | L8: A | M8: Pass | N8: ARWC second set | O8: https://indiankanoon.org/doc/54814974/
A9: INV-008 | B9: ARWC-ISR-001 | C9: Provisional record | D9: Roman Zadorov | E9: רומן זדורוב | F9: Israel | G9: Katzrin | H9: Murder | I9: 2015 | J9: 2023 | K9: Retrial acquittal | L9: A | M9: Pass | N9: ARWC second set | O9: https://www.gov.il/BlobFolder/dynamiccollectorresultitem/decision502-07/he/502-07.pdf
A10: INV-009 | B10: ARWC-PAK-001 | C10: Provisional record | D10: Zulfikar Ali Bhutto | E10: ذوالفقار علی بھٹو | F10: Pakistan | G10: Lahore | H10: Murder (conspiracy, abetment) | I10: 1979 | J10: 2024 | K10: Supreme Court advisory opinion: no fair trial; conviction stands | L10: B | M10: Pass | N10: ARWC second set | O10: https://www.dawn.com/news/1819573 | P10: Executed 1979
A11: INV-010 | B11: ARWC-SGP-001 | C11: Provisional record | D11: Ilechukwu Uchechukwu Chukwudi | F11: Singapore | H11: Drug trafficking (capital) | I11: 2015 | J11: 2020 | K11: Acquittal on reopening of concluded appeal | L11: A | M11: Pass | N11: ARWC second set | O11: https://www.elitigation.sg/gd/s/2020_SGCA_90
A12: INV-011 | B12: ARWC-VNM-001 | C12: Provisional record | D12: Nguyen Thanh Chan | E12: Nguyễn Thanh Chấn | F12: Vietnam | G12: Bắc Giang | H12: Murder | I12: 2004 | J12: 2013 | K12: Final judgments annulled on reopening; apology and compensation 2015 | L12: A, B | M12: Pass | N12: ARWC second set | O12: https://baochinhphu.vn/tam-dinh-chi-thi-hanh-an-tu-chung-than-1-pham-nhan-102152351.htm
A13: INV-012 | B13: ARWC-IDN-001 | C13: Pending | D13: Sengkon and Karta | F13: Indonesia | G13: Bekasi | H13: Robbery and murder | I13: 1978 | J13: 1981 | K13: Supreme Court review (PK) granted, as reported | L13: A | M13: Likely (date to confirm) | N13: ARWC first set | O13: https://www.thejakartapost.com/news/2008/09/02/editorial-defending-wrong-judgment.html | P13: Documentation FAIL until the PK decision is cited
A14: INV-013 | B14: EXC-HKG-001 | C14: Excluded (worked example) | D14: A (anonymized) | F14: Hong Kong | H14: Conspiracy to rob | J14: 2015 | K14: Quashed on ordinary appeal | M14: Fail | N14: ARWC first set | O14: https://www.doj.gov.hk/en/notable_judgments/pdf/HCAL_176_2018e.pdf | P14: Worked exclusion: never final
A15: INV-014 | C15: Set aside in pilot | D15: Hubert Webb and co-accused (Vizconde case) | F15: Philippines | H15: Rape with homicide | J15: 2010 | K15: Supreme Court acquittal on appeal | M15: Fail | N15: ARWC second set (candidates list) | P15: Corrected on ordinary appeal
A16: INV-015 | C16: Set aside in pilot | D16: Asia Bibi | F16: Pakistan | H16: Blasphemy | J16: 2018 | K16: Supreme Court acquittal on appeal | M16: Fail | N16: ARWC second set (candidates list) | P16: Corrected on ordinary appeal
A17: INV-016 | C17: Set aside in pilot | D17: Sandeep Lamichhane | F17: Nepal | H17: Rape | J17: 2024 | K17: High Court acquittal on appeal | M17: Fail | N17: ARWC second set (candidates list) | P17: Corrected on ordinary appeal
A18: INV-017 | C18: Set aside in pilot | D18: Born Samnang and Sok Sam Oeun | F18: Cambodia | H18: Murder | K18: Decided within appeal and cassation chain, as reported | M18: Doubtful | N18: ARWC second set (candidates list) | P18: Not checked further
A19: INV-018 | C19: Set aside in pilot | D19: Ilgar Mammadov | F19: Azerbaijan | H19: Organizing mass disorder | J19: 2020 | K19: Supreme Court acquittal after ECtHR judgments | L19: A? | M19: To check | N19: ARWC second set (candidates list) | P19: Region scope (South Caucasus) undecided; political case
A20: INV-019 | C20: Set aside in pilot | D20: Sledgehammer (Balyoz) defendants | F20: Turkey | H20: Coup plot | J20: 2015 | K20: Retrial acquittal after Constitutional Court ruling | L20: A? | M20: To check | N20: ARWC second set (candidates list) | P20: Region scope (Anatolia) undecided; political case
A21: INV-020 | C21: Set aside in pilot | D21: Anwar Ibrahim | F21: Malaysia | H21: Sodomy | J21: 2018 | K21: Full royal pardon | L21: C? | M21: To check | N21: ARWC second set (candidates list) | P21: Qualifies only if documents tie pardon to wrongful-conviction concerns
A22: INV-021 | C22: Candidate - not screened | D22: She Xianglin | E22: 佘祥林 | F22: China | G22: Hubei | H22: Intentional homicide | I22: 1998 | J22: 2005 | K22: Retrial acquittal; alleged victim reappeared | L22: A | M22: Likely | N22: USALI archive | O22: https://usali.org/wc-case-archive/she-xianglin-case
A23: INV-022 | C23: Candidate - not screened | D23: Zhao Zuohai | E23: 赵作海 | F23: China | G23: Henan | H23: Intentional homicide | I23: 2002 | J23: 2010 | K23: Retrial acquittal; alleged victim reappeared | L23: A | M23: Likely | N23: USALI archive | O23: https://usali.org/wc-case-archive/zhao-zuohai-case
A24: INV-023 | C24: Candidate - not screened | D24: Huugjilt (Huge Jiletu) | E24: 呼格吉勒图 | F24: China | G24: Inner Mongolia | H24: Rape and murder | I24: 1996 | J24: 2014 | K24: Posthumous retrial acquittal; executed 1996 | L24: A | M24: Likely | N24: USALI archive | O24: https://usali.org/wc-case-archive/huge-jiletu-case | P24: Another man later confessed
A25: INV-024 | C25: Candidate - not screened | D25: Zhang Hui and Zhang Gaoping | E25: 张辉、张高平 | F25: China | G25: Zhejiang | H25: Rape (victim killed) | I25: 2004 | J25: 2013 | K25: Retrial acquittal; state compensation | L25: A, B? | M25: Likely | N25: USALI archive | O25: https://usali.org/wc-case-archive/zhang-hui-zhang-gaoping-case | P25: Jailhouse informant evidence
A26: INV-025 | C26: Candidate - not screened | D26: Tian Weidong and four others | E26: 田伟冬等五人 | F26: China | G26: Zhejiang (Xiaoshan) | H26: Robbery and murder | J26: 2013 | K26: Retrial acquittal | L26: A | M26: Likely | N26: USALI archive | O26: https://usali.org/wc-case-archive/tian-weidong-case | P26: Xiaoshan five; real perpetrator confessed
A27: INV-026 | C27: Candidate - not screened | D27: Du Peiwu | E27: 杜培武 | F27: China | G27: Yunnan | H27: Intentional homicide | J27: 2000 | K27: Acquittal by Yunnan High Court after real perpetrator found | L27: A | M27: To check | N27: USALI archive | O27: https://usali.org/wc-case-archive/du-peiwu-case | P27: Check whether conviction was final before 2000
A28: INV-027 | C28: Candidate - not screened | D28: Bai Chunrong | E28: 白春荣 | F28: China | G28: Guangdong (Foshan) | H28: Theft | I28: 1988 | J28: 2014 | K28: Acquittal on insufficient evidence | L28: A | M28: Likely | N28: USALI archive | O28: https://usali.org/wc-case-archive/bai-chun-rong-case | P28: Sentence already served
A29: INV-028 | C29: Candidate - not screened | D29: Shen Liujin (Fang Weishe) | E29: 沈六斤 | F29: China | H29: Intentional homicide | J29: 2016 | K29: High court acquittal on misidentification | L29: A | M29: To check | N29: USALI archive | O29: https://usali.org/wc-case-archive/shen-liujin-murder-case
A30: INV-029 | C30: Candidate - not screened | D30: Guo Li | E30: 郭利 | F30: China | G30: Guangdong | H30: Extortion | J30: 2017 | K30: Acquittal, as reported | L30: A | M30: To check | N30: USALI archive | O30: https://usali.org/wc-case-archive/guo-li-racketeering-case
A31: INV-030 | C31: Candidate - not screened | D31: Zeng Fannian | E31: 曾凡年 | F31: China | H31: Extortion | K31: To check | M31: To check | N31: USALI archive | O31: https://usali.org/wc-case-archive/zeng-fannian-extortion-case
A32: INV-031 | C32: Candidate - not screened | D32: Zeng Aiyun | E32: 曾爱云 | F32: China | G32: Hunan (Xiangtan) | H32: Intentional homicide | K32: Acquittal, as reported | M32: Doubtful | N32: USALI archive | O32: https://usali.org/wc-case-archive/zeng-aiyun-murder-case | P32: 2004 conviction vacated on appeal in 2005; may never have been final
A33: INV-032 | C33: Candidate - not screened | D33: Qian Renfeng | E33: 钱仁风 | F33: China | G33: Yunnan | H33: Poisoning | K33: Retrial ordered 2015; outcome to check | M33: To check | N33: USALI archive | O33: https://usali.org/wc-case-archive/qian-renfeng-poison-case
A34: INV-033 | C34: Candidate - not screened | D34: Fang Junjin | E34: 方俊金 | F34: China | H34: Illegal intrusion into a dwelling | K34: To check | M34: To check | N34: USALI archive | O34: https://usali.org/wc-case-archive/fang-junjin-case
A35: INV-034 | C35: Candidate - not screened | D35: Tan Xiuyi | E35: 谭修义 | F35: China | H35: Rape and murder | K35: Exonerated, as reported | M35: To check | N35: USALI archive | O35: https://usali.org/wc-case-archive/tan-xiuyi-rape-and-murder-case | P35: 1993 offense
A36: INV-035 | C36: Candidate - not screened | D36: Lu Rongxin | E36: 卢荣新 | F36: China | H36: Rape and murder | I36: 2015 | J36: 2017 | K36: High court acquittal; DNA did not match | M36: Doubtful | N36: USALI archive | O36: https://usali.org/wc-case-archive/lu-rongxin-rape-and-murder-case | P36: Death sentence 2015, acquitted 2017: check whether ever final
A37: INV-036 | C37: Candidate - not screened | D37: Wang Benyu | E37: 王本余 | F37: China | H37: Murder and rape of a girl | J37: 2013 | K37: Acquittal after real perpetrator confessed | L37: A | M37: To check | N37: USALI archive | O37: https://usali.org/wc-case-archive/wang-benyu-case
A38: INV-037 | C38: Candidate - not screened | D38: Zhang Guangxiang | E38: 张光祥 | F38: China | G38: Guizhou | H38: Robbery | K38: Acquittal about ten years after incarceration, as reported | M38: To check | N38: USALI archive | O38: https://usali.org/wc-case-archive/new-zhang-guangxiang-robbery-case- | P38: 1999 offense
A39: INV-038 | C39: Candidate - not screened | D39: Yang Botao | E39: 杨波涛 | F39: China | G39: Henan (Shangqiu) | H39: Intentional homicide | K39: To check | M39: To check | N39: USALI archive | O39: https://usali.org/wc-case-archive/yang-botao-case
A40: INV-039 | C40: Candidate - not screened | D40: Wu Chunhong | E40: 吴春红 | F40: China | G40: Henan (Minquan) | H40: Intentional homicide (poisoning) | J40: 2020 | K40: Retrial acquittal | L40: A | M40: Likely | N40: USALI archive | O40: https://usali.org/wc-case-archive/wu-chunhong-murder-case | P40: Life sentence on fourth conviction
...

Sheet Summary
A1: Jurisdiction | B1: Verified record | C1: Provisional record | D1: Pending | E1: Excluded (worked example) | F1: Set aside in pilot | G1: Candidate - not screened | H1: Total
A2: Azerbaijan | B2: =COUNTIFS(Cases!$F:$F,$A2,Cases!$C:$C,B$1) -> 0 | C2: =COUNTIFS(Cases!$F:$F,$A2,Cases!$C:$C,C$1) -> 0 | D2: =COUNTIFS(Cases!$F:$F,$A2,Cases!$C:$C,D$1) -> 0 | E2: =COUNTIFS(Cases!$F:$F,$A2,Cases!$C:$C,E$1) -> 0 | F2: =COUNTIFS(Cases!$F:$F,$A2,Cases!$C:$C,F$1) -> 1 | G2: =COUNTIFS(Cases!$F:$F,$A2,Cases!$C:$C,G$1) -> 0 | H2: =SUM(B2:G2) -> 1
A3: Cambodia | B3: =COUNTIFS(Cases!$F:$F,$A3,Cases!$C:$C,B$1) -> 0 | C3: =COUNTIFS(Cases!$F:$F,$A3,Cases!$C:$C,C$1) -> 0 | D3: =COUNTIFS(Cases!$F:$F,$A3,Cases!$C:$C,D$1) -> 0 | E3: =COUNTIFS(Cases!$F:$F,$A3,Cases!$C:$C,E$1) -> 0 | F3: =COUNTIFS(Cases!$F:$F,$A3,Cases!$C:$C,F$1) -> 1 | G3: =COUNTIFS(Cases!$F:$F,$A3,Cases!$C:$C,G$1) -> 0 | H3: =SUM(B3:G3) -> 1
A4: China | B4: =COUNTIFS(Cases!$F:$F,$A4,Cases!$C:$C,B$1) -> 1 | C4: =COUNTIFS(Cases!$F:$F,$A4,Cases!$C:$C,C$1) -> 1 | D4: =COUNTIFS(Cases!$F:$F,$A4,Cases!$C:$C,D$1) -> 0 | E4: =COUNTIFS(Cases!$F:$F,$A4,Cases!$C:$C,E$1) -> 0 | F4: =COUNTIFS(Cases!$F:$F,$A4,Cases!$C:$C,F$1) -> 0 | G4: =COUNTIFS(Cases!$F:$F,$A4,Cases!$C:$C,G$1) -> 35 | H4: =SUM(B4:G4) -> 37
A5: Hong Kong | B5: =COUNTIFS(Cases!$F:$F,$A5,Cases!$C:$C,B$1) -> 0 | C5: =COUNTIFS(Cases!$F:$F,$A5,Cases!$C:$C,C$1) -> 0 | D5: =COUNTIFS(Cases!$F:$F,$A5,Cases!$C:$C,D$1) -> 0 | E5: =COUNTIFS(Cases!$F:$F,$A5,Cases!$C:$C,E$1) -> 1 | F5: =COUNTIFS(Cases!$F:$F,$A5,Cases!$C:$C,F$1) -> 0 | G5: =COUNTIFS(Cases!$F:$F,$A5,Cases!$C:$C,G$1) -> 0 | H5: =SUM(B5:G5) -> 1
A6: India | B6: =COUNTIFS(Cases!$F:$F,$A6,Cases!$C:$C,B$1) -> 0 | C6: =COUNTIFS(Cases!$F:$F,$A6,Cases!$C:$C,C$1) -> 1 | D6: =COUNTIFS(Cases!$F:$F,$A6,Cases!$C:$C,D$1) -> 0 | E6: =COUNTIFS(Cases!$F:$F,$A6,Cases!$C:$C,E$1) -> 0 | F6: =COUNTIFS(Cases!$F:$F,$A6,Cases!$C:$C,F$1) -> 0 | G6: =COUNTIFS(Cases!$F:$F,$A6,Cases!$C:$C,G$1) -> 0 | H6: =SUM(B6:G6) -> 1
A7: Indonesia | B7: =COUNTIFS(Cases!$F:$F,$A7,Cases!$C:$C,B$1) -> 0 | C7: =COUNTIFS(Cases!$F:$F,$A7,Cases!$C:$C,C$1) -> 0 | D7: =COUNTIFS(Cases!$F:$F,$A7,Cases!$C:$C,D$1) -> 1 | E7: =COUNTIFS(Cases!$F:$F,$A7,Cases!$C:$C,E$1) -> 0 | F7: =COUNTIFS(Cases!$F:$F,$A7,Cases!$C:$C,F$1) -> 0 | G7: =COUNTIFS(Cases!$F:$F,$A7,Cases!$C:$C,G$1) -> 0 | H7: =SUM(B7:G7) -> 1
A8: Israel | B8: =COUNTIFS(Cases!$F:$F,$A8,Cases!$C:$C,B$1) -> 0 | C8: =COUNTIFS(Cases!$F:$F,$A8,Cases!$C:$C,C$1) -> 1 | D8: =COUNTIFS(Cases!$F:$F,$A8,Cases!$C:$C,D$1) -> 0 | E8: =COUNTIFS(Cases!$F:$F,$A8,Cases!$C:$C,E$1) -> 0 | F8: =COUNTIFS(Cases!$F:$F,$A8,Cases!$C:$C,F$1) -> 0 | G8: =COUNTIFS(Cases!$F:$F,$A8,Cases!$C:$C,G$1) -> 1 | H8: =SUM(B8:G8) -> 2
A9: Japan | B9: =COUNTIFS(Cases!$F:$F,$A9,Cases!$C:$C,B$1) -> 0 | C9: =COUNTIFS(Cases!$F:$F,$A9,Cases!$C:$C,C$1) -> 2 | D9: =COUNTIFS(Cases!$F:$F,$A9,Cases!$C:$C,D$1) -> 0 | E9: =COUNTIFS(Cases!$F:$F,$A9,Cases!$C:$C,E$1) -> 0 | F9: =COUNTIFS(Cases!$F:$F,$A9,Cases!$C:$C,F$1) -> 0 | G9: =COUNTIFS(Cases!$F:$F,$A9,Cases!$C:$C,G$1) -> 13 | H9: =SUM(B9:G9) -> 15
A10: Korea | B10: =COUNTIFS(Cases!$F:$F,$A10,Cases!$C:$C,B$1) -> 0 | C10: =COUNTIFS(Cases!$F:$F,$A10,Cases!$C:$C,C$1) -> 1 | D10: =COUNTIFS(Cases!$F:$F,$A10,Cases!$C:$C,D$1) -> 0 | E10: =COUNTIFS(Cases!$F:$F,$A10,Cases!$C:$C,E$1) -> 0 | F10: =COUNTIFS(Cases!$F:$F,$A10,Cases!$C:$C,F$1) -> 0 | G10: =COUNTIFS(Cases!$F:$F,$A10,Cases!$C:$C,G$1) -> 7 | H10: =SUM(B10:G10) -> 8
A11: Malaysia | B11: =COUNTIFS(Cases!$F:$F,$A11,Cases!$C:$C,B$1) -> 0 | C11: =COUNTIFS(Cases!$F:$F,$A11,Cases!$C:$C,C$1) -> 0 | D11: =COUNTIFS(Cases!$F:$F,$A11,Cases!$C:$C,D$1) -> 0 | E11: =COUNTIFS(Cases!$F:$F,$A11,Cases!$C:$C,E$1) -> 0 | F11: =COUNTIFS(Cases!$F:$F,$A11,Cases!$C:$C,F$1) -> 1 | G11: =COUNTIFS(Cases!$F:$F,$A11,Cases!$C:$C,G$1) -> 0 | H11: =SUM(B11:G11) -> 1
A12: Nepal | B12: =COUNTIFS(Cases!$F:$F,$A12,Cases!$C:$C,B$1) -> 0 | C12: =COUNTIFS(Cases!$F:$F,$A12,Cases!$C:$C,C$1) -> 0 | D12: =COUNTIFS(Cases!$F:$F,$A12,Cases!$C:$C,D$1) -> 0 | E12: =COUNTIFS(Cases!$F:$F,$A12,Cases!$C:$C,E$1) -> 0 | F12: =COUNTIFS(Cases!$F:$F,$A12,Cases!$C:$C,F$1) -> 1 | G12: =COUNTIFS(Cases!$F:$F,$A12,Cases!$C:$C,G$1) -> 0 | H12: =SUM(B12:G12) -> 1
A13: Pakistan | B13: =COUNTIFS(Cases!$F:$F,$A13,Cases!$C:$C,B$1) -> 0 | C13: =COUNTIFS(Cases!$F:$F,$A13,Cases!$C:$C,C$1) -> 1 | D13: =COUNTIFS(Cases!$F:$F,$A13,Cases!$C:$C,D$1) -> 0 | E13: =COUNTIFS(Cases!$F:$F,$A13,Cases!$C:$C,E$1) -> 0 | F13: =COUNTIFS(Cases!$F:$F,$A13,Cases!$C:$C,F$1) -> 1 | G13: =COUNTIFS(Cases!$F:$F,$A13,Cases!$C:$C,G$1) -> 0 | H13: =SUM(B13:G13) -> 2
... A18: Vietnam | B18: =COUNTIFS(Cases!$F:$F,$A18,Cases!$C:$C,B$1) -> 0 | C18: =COUNTIFS(Cases!$F:$F,$A18,Cases!$C:$C,C$1) -> 1 | D18: =COUNTIFS(Cases!$F:$F,$A18,Cases!$C:$C,D$1) -> 0 | E18: =COUNTIFS(Cases!$F:$F,$A18,Cases!$C:$C,E$1) -> 0 | F18: =COUNTIFS(Cases!$F:$F,$A18,Cases!$C:$C,F$1) -> 0 | G18: =COUNTIFS(Cases!$F:$F,$A18,Cases!$C:$C,G$1) -> 2 | H18: =SUM(B18:G18) -> 3
A19: Total | B19: =SUM(B2:B18) -> 1 | C19: =SUM(C2:C18) -> 10 | D19: =SUM(D2:D18) -> 1 | E19: =SUM(E2:E18) -> 1 | F19: =SUM(F2:F18) -> 7 | G19: =SUM(G2:G18) -> 68 | H19: =SUM(H2:H18) -> 88
A21: Candidates by finality check
A22: Likely | B22: =COUNTIFS(Cases!$C:$C,"Candidate - not screened",Cases!$M:$M,A22) -> 34
A23: Doubtful | B23: =COUNTIFS(Cases!$C:$C,"Candidate - not screened",Cases!$M:$M,A23) -> 5
A24: To check | B24: =COUNTIFS(Cases!$C:$C,"Candidate - not screened",Cases!$M:$M,A24) -> 29
A25: Fail | B25: =COUNTIFS(Cases!$C:$C,"Candidate - not screened",Cases!$M:$M,A25) -> 0

Sheet Sources to mine
A1: Source | B1: Jurisdiction | C1: What it holds | D1: URL | E1: Status in this inventory
A2: China Wrongful Convictions Case Archive (USALI, NYU) | B2: China | C2: English-language case pages; more than 170 overturned convictions since 1979, on appeal or retrial | D2: https://usali.org/china-wrongful-convictions-case-archive | E2: About 30 case pages found by search; full index not reachable from the build environment. Archive also includes cases corrected on ordinary appeal, which ARWC excludes
A3: Taiwan Innocence Project: Database of Criminal Retrial-Acquittals, 1991-2026 | B3: Taiwan | C3: 308 retrial-based acquittals since 1991 (framework paper) | D3: https://twinnocenceproject.org/database/ | E3: Not reachable from the build environment; nine well-known cases listed from other sources. Ask TIP (Ko) for an export
A4: Innocence Project Japan | B4: Japan | C4: Case work and commentary | D4: https://innocenceprojectjapan.org/en/home-2 | E4: Not reachable from the build environment; cases listed from public reporting. Nishi's data cover retrial acquittals
A5: Japan Federation of Bar Associations (JFBA) retrial support cases | B5: Japan | C5: Bar-supported retrial cases | D5: https://www.nichibenren.or.jp/ | E5: Not yet mined
A6: Korea Truth and Reconciliation Commission; court retrial records | B6: Korea | C6: Commission-recommended retrials, many political-era cases | E6: Only a few listed; likely dozens more
A7: Taiwan Alliance to End the Death Penalty / Talking Taiwan list | B7: Taiwan | C7: Death-row exonerations | D7: https://talkingtaiwan.com/?p=6809 | E7: Used for three cases
A8: Le et al. (2024) systematic review | B8: Asia | C8: Cases discussed in the literature across Asian countries | E8: Not yet mined
